Workbook

Sheet Dashboard
A1: BACKLOG DASHBOARD
A2: Every figure below is a live formula over the Backlog sheet — change a Status there and this updates.
A4: OVERALL | F4: BY EPIC
A5: Metric | B5: Value | F5: Epic | G5: Name | H5: Phase | I5: Stories | J5: Est. days | K5: Closed | L5: % Done
A6: Total stories | B6: =COUNTA(Backlog!$A$5:$A$219) | F6: E00 | G6: FOUNDATION | H6: 0 | I6: =COUNTIF(Backlog!$B$5:$B$219,$F6) | J6: =SUMIF(Backlog!$B$5:$B$219,$F6,Backlog!$J$5:$J$219) | K6: =COUNTIFS(Backlog!$B$5:$B$219,$F6,Backlog!$E$5:$E$219,"Closed") | L6: =IFERROR($K6/$I6,0)
A7: Total estimated days | B7: =SUM(Backlog!$J$5:$J$219) | F7: E01 | G7: PERSISTENCE & DATA LAYER | H7: 1 | I7: =COUNTIF(Backlog!$B$5:$B$219,$F7) | J7: =SUMIF(Backlog!$B$5:$B$219,$F7,Backlog!$J$5:$J$219) | K7: =COUNTIFS(Backlog!$B$5:$B$219,$F7,Backlog!$E$5:$E$219,"Closed") | L7: =IFERROR($K7/$I7,0)
A8: Closed | B8: =COUNTIF(Backlog!$E$5:$E$219,"Closed") | F8: E02 | G8: BROKER INTEGRATION | H8: 1 | I8: =COUNTIF(Backlog!$B$5:$B$219,$F8) | J8: =SUMIF(Backlog!$B$5:$B$219,$F8,Backlog!$J$5:$J$219) | K8: =COUNTIFS(Backlog!$B$5:$B$219,$F8,Backlog!$E$5:$E$219,"Closed") | L8: =IFERROR($K8/$I8,0)
A9: In flight (Active→QA) | B9: =SUMPRODUCT(COUNTIF(Backlog!$E$5:$E$219,{"Active","Development In-Progress","Development Completed","QA In-Progress","QA-Success"})) | F9: E03 | G9: HISTORICAL DATA | H9: 1 | I9: =COUNTIF(Backlog!$B$5:$B$219,$F9) | J9: =SUMIF(Backlog!$B$5:$B$219,$F9,Backlog!$J$5:$J$219) | K9: =COUNTIFS(Backlog!$B$5:$B$219,$F9,Backlog!$E$5:$E$219,"Closed") | L9: =IFERROR($K9/$I9,0)
A10: Not started (New) | B10: =COUNTIF(Backlog!$E$5:$E$219,"New") | F10: E04 | G10: INDIA HAZARD LISTS | H10: 1 | I10: =COUNTIF(Backlog!$B$5:$B$219,$F10) | J10: =SUMIF(Backlog!$B$5:$B$219,$F10,Backlog!$J$5:$J$219) | K10: =COUNTIFS(Backlog!$B$5:$B$219,$F10,Backlog!$E$5:$E$219,"Closed") | L10: =IFERROR($K10/$I10,0)
A11: Blocked / On Hold | B11: =COUNTIF(Backlog!$E$5:$E$219,"Blocked")+COUNTIF(Backlog!$E$5:$E$219,"On Hold") | F11: E05 | G11: MARKET DATA INGESTION | H11: 1 | I11: =COUNTIF(Backlog!$B$5:$B$219,$F11) | J11: =SUMIF(Backlog!$B$5:$B$219,$F11,Backlog!$J$5:$J$219) | K11: =COUNTIFS(Backlog!$B$5:$B$219,$F11,Backlog!$E$5:$E$219,"Closed") | L11: =IFERROR($K11/$I11,0)
A12: % Complete | B12: =IFERROR(COUNTIF(Backlog!$E$5:$E$219,"Closed")/COUNTA(Backlog!$A$5:$A$219),0) | F12: E06 | G12: TECHNICAL ANALYSIS ENGINE | H12: 2 | I12: =COUNTIF(Backlog!$B$5:$B$219,$F12) | J12: =SUMIF(Backlog!$B$5:$B$219,$F12,Backlog!$J$5:$J$219) | K12: =COUNTIFS(Backlog!$B$5:$B$219,$F12,Backlog!$E$5:$E$219,"Closed") | L12: =IFERROR($K12/$I12,0)
A13: Days closed | B13: =SUMIF(Backlog!$E$5:$E$219,"Closed",Backlog!$J$5:$J$219) | F13: E07 | G13: UNIVERSE & SCORING | H13: 2 | I13: =COUNTIF(Backlog!$B$5:$B$219,$F13) | J13: =SUMIF(Backlog!$B$5:$B$219,$F13,Backlog!$J$5:$J$219) | K13: =COUNTIFS(Backlog!$B$5:$B$219,$F13,Backlog!$E$5:$E$219,"Closed") | L13: =IFERROR($K13/$I13,0)
A14: Days remaining | B14: =SUM(Backlog!$J$5:$J$219)-SUMIF(Backlog!$E$5:$E$219,"Closed",Backlog!$J$5:$J$219) | F14: E08 | G14: NEWS INTELLIGENCE | H14: 3 | I14: =COUNTIF(Backlog!$B$5:$B$219,$F14) | J14: =SUMIF(Backlog!$B$5:$B$219,$F14,Backlog!$J$5:$J$219) | K14: =COUNTIFS(Backlog!$B$5:$B$219,$F14,Backlog!$E$5:$E$219,"Closed") | L14: =IFERROR($K14/$I14,0)
F15: E09 | G15: MACRO CONTEXT | H15: 3 | I15: =COUNTIF(Backlog!$B$5:$B$219,$F15) | J15: =SUMIF(Backlog!$B$5:$B$219,$F15,Backlog!$J$5:$J$219) | K15: =COUNTIFS(Backlog!$B$5:$B$219,$F15,Backlog!$E$5:$E$219,"Closed") | L15: =IFERROR($K15/$I15,0)
A16: BY STATUS | F16: E10 | G16: AI LAYER | H16: 3 | I16: =COUNTIF(Backlog!$B$5:$B$219,$F16) | J16: =SUMIF(Backlog!$B$5:$B$219,$F16,Backlog!$J$5:$J$219) | K16: =COUNTIFS(Backlog!$B$5:$B$219,$F16,Backlog!$E$5:$E$219,"Closed") | L16: =IFERROR($K16/$I16,0)
A17: Status | B17: Stories | C17: % of total | D17: Est. days | F17: E11 | G17: PRE-MARKET ENGINE | H17: 3 | I17: =COUNTIF(Backlog!$B$5:$B$219,$F17) | J17: =SUMIF(Backlog!$B$5:$B$219,$F17,Backlog!$J$5:$J$219) | K17: =COUNTIFS(Backlog!$B$5:$B$219,$F17,Backlog!$E$5:$E$219,"Closed") | L17: =IFERROR($K17/$I17,0)
A18: New | B18: =COUNTIF(Backlog!$E$5:$E$219,$A18) | C18: =IFERROR($B18/COUNTA(Backlog!$A$5:$A$219),0) | D18: =SUMIF(Backlog!$E$5:$E$219,$A18,Backlog!$J$5:$J$219) | F18: E12 | G18: STRATEGY ENGINE | H18: 5 | I18: =COUNTIF(Backlog!$B$5:$B$219,$F18) | J18: =SUMIF(Backlog!$B$5:$B$219,$F18,Backlog!$J$5:$J$219) | K18: =COUNTIFS(Backlog!$B$5:$B$219,$F18,Backlog!$E$5:$E$219,"Closed") | L18: =IFERROR($K18/$I18,0)
A19: Business Review | B19: =COUNTIF(Backlog!$E$5:$E$219,$A19) | C19: =IFERROR($B19/COUNTA(Backlog!$A$5:$A$219),0) | D19: =SUMIF(Backlog!$E$5:$E$219,$A19,Backlog!$J$5:$J$219) | F19: E13 | G19: SIGNAL ENGINE | H19: 4 | I19: =COUNTIF(Backlog!$B$5:$B$219,$F19) | J19: =SUMIF(Backlog!$B$5:$B$219,$F19,Backlog!$J$5:$J$219) | K19: =COUNTIFS(Backlog!$B$5:$B$219,$F19,Backlog!$E$5:$E$219,"Closed") | L19: =IFERROR($K19/$I19,0)
A20: Business Approved | B20: =COUNTIF(Backlog!$E$5:$E$219,$A20) | C20: =IFERROR($B20/COUNTA(Backlog!$A$5:$A$219),0) | D20: =SUMIF(Backlog!$E$5:$E$219,$A20,Backlog!$J$5:$J$219) | F20: E14 | G20: RISK ENGINE | H20: 5 | I20: =COUNTIF(Backlog!$B$5:$B$219,$F20) | J20: =SUMIF(Backlog!$B$5:$B$219,$F20,Backlog!$J$5:$J$219) | K20: =COUNTIFS(Backlog!$B$5:$B$219,$F20,Backlog!$E$5:$E$219,"Closed") | L20: =IFERROR($K20/$I20,0)
A21: Active | B21: =COUNTIF(Backlog!$E$5:$E$219,$A21) | C21: =IFERROR($B21/COUNTA(Backlog!$A$5:$A$219),0) | D21: =SUMIF(Backlog!$E$5:$E$219,$A21,Backlog!$J$5:$J$219) | F21: E15 | G21: EXECUTION & POSITIONS | H21: 5 | I21: =COUNTIF(Backlog!$B$5:$B$219,$F21) | J21: =SUMIF(Backlog!$B$5:$B$219,$F21,Backlog!$J$5:$J$219) | K21: =COUNTIFS(Backlog!$B$5:$B$219,$F21,Backlog!$E$5:$E$219,"Closed") | L21: =IFERROR($K21/$I21,0)
A22: Development In-Progress | B22: =COUNTIF(Backlog!$E$5:$E$219,$A22) | C22: =IFERROR($B22/COUNTA(Backlog!$A$5:$A$219),0) | D22: =SUMIF(Backlog!$E$5:$E$219,$A22,Backlog!$J$5:$J$219) | F22: E16 | G22: AUTONOMY & APPROVAL | H22: 5 | I22: =COUNTIF(Backlog!$B$5:$B$219,$F22) | J22: =SUMIF(Backlog!$B$5:$B$219,$F22,Backlog!$J$5:$J$219) | K22: =COUNTIFS(Backlog!$B$5:$B$219,$F22,Backlog!$E$5:$E$219,"Closed") | L22: =IFERROR($K22/$I22,0)
A23: Development Completed | B23: =COUNTIF(Backlog!$E$5:$E$219,$A23) | C23: =IFERROR($B23/COUNTA(Backlog!$A$5:$A$219),0) | D23: =SUMIF(Backlog!$E$5:$E$219,$A23,Backlog!$J$5:$J$219) | F23: E17 | G23: DASHBOARD UI | H23: 4/6 | I23: =COUNTIF(Backlog!$B$5:$B$219,$F23) | J23: =SUMIF(Backlog!$B$5:$B$219,$F23,Backlog!$J$5:$J$219) | K23: =COUNTIFS(Backlog!$B$5:$B$219,$F23,Backlog!$E$5:$E$219,"Closed") | L23: =IFERROR($K23/$I23,0)
A24: QA In-Progress | B24: =COUNTIF(Backlog!$E$5:$E$219,$A24) | C24: =IFERROR($B24/COUNTA(Backlog!$A$5:$A$219),0) | D24: =SUMIF(Backlog!$E$5:$E$219,$A24,Backlog!$J$5:$J$219) | F24: E18 | G24: ADMIN UI | H24: 6 | I24: =COUNTIF(Backlog!$B$5:$B$219,$F24) | J24: =SUMIF(Backlog!$B$5:$B$219,$F24,Backlog!$J$5:$J$219) | K24: =COUNTIFS(Backlog!$B$5:$B$219,$F24,Backlog!$E$5:$E$219,"Closed") | L24: =IFERROR($K24/$I24,0)
A25: QA-Success | B25: =COUNTIF(Backlog!$E$5:$E$219,$A25) | C25: =IFERROR($B25/COUNTA(Backlog!$A$5:$A$219),0) | D25: =SUMIF(Backlog!$E$5:$E$219,$A25,Backlog!$J$5:$J$219) | F25: E19 | G25: NOTIFICATIONS | H25: 3/4 | I25: =COUNTIF(Backlog!$B$5:$B$219,$F25) | J25: =SUMIF(Backlog!$B$5:$B$219,$F25,Backlog!$J$5:$J$219) | K25: =COUNTIFS(Backlog!$B$5:$B$219,$F25,Backlog!$E$5:$E$219,"Closed") | L25: =IFERROR($K25/$I25,0)
A26: QA-Fail | B26: =COUNTIF(Backlog!$E$5:$E$219,$A26) | C26: =IFERROR($B26/COUNTA(Backlog!$A$5:$A$219),0) | D26: =SUMIF(Backlog!$E$5:$E$219,$A26,Backlog!$J$5:$J$219) | F26: E20 | G26: OBSERVABILITY | H26: 6 | I26: =COUNTIF(Backlog!$B$5:$B$219,$F26) | J26: =SUMIF(Backlog!$B$5:$B$219,$F26,Backlog!$J$5:$J$219) | K26: =COUNTIFS(Backlog!$B$5:$B$219,$F26,Backlog!$E$5:$E$219,"Closed") | L26: =IFERROR($K26/$I26,0)
A27: Closed | B27: =COUNTIF(Backlog!$E$5:$E$219,$A27) | C27: =IFERROR($B27/COUNTA(Backlog!$A$5:$A$219),0) | D27: =SUMIF(Backlog!$E$5:$E$219,$A27,Backlog!$J$5:$J$219) | F27: E21 | G27: COMPLIANCE & TAX | H27: 6 | I27: =COUNTIF(Backlog!$B$5:$B$219,$F27) | J27: =SUMIF(Backlog!$B$5:$B$219,$F27,Backlog!$J$5:$J$219) | K27: =COUNTIFS(Backlog!$B$5:$B$219,$F27,Backlog!$E$5:$E$219,"Closed") | L27: =IFERROR($K27/$I27,0)
A28: Removed | B28: =COUNTIF(Backlog!$E$5:$E$219,$A28) | C28: =IFERROR($B28/COUNTA(Backlog!$A$5:$A$219),0) | D28: =SUMIF(Backlog!$E$5:$E$219,$A28,Backlog!$J$5:$J$219) | F28: E22 | G28: TESTING & VALIDATION | H28: 7 | I28: =COUNTIF(Backlog!$B$5:$B$219,$F28) | J28: =SUMIF(Backlog!$B$5:$B$219,$F28,Backlog!$J$5:$J$219) | K28: =COUNTIFS(Backlog!$B$5:$B$219,$F28,Backlog!$E$5:$E$219,"Closed") | L28: =IFERROR($K28/$I28,0)
A29: Moved to Backlog | B29: =COUNTIF(Backlog!$E$5:$E$219,$A29) | C29: =IFERROR($B29/COUNTA(Backlog!$A$5:$A$219),0) | D29: =SUMIF(Backlog!$E$5:$E$219,$A29,Backlog!$J$5:$J$219) | F29: E23 | G29: DEPLOYMENT & OPS | H29: 7/8 | I29: =COUNTIF(Backlog!$B$5:$B$219,$F29) | J29: =SUMIF(Backlog!$B$5:$B$219,$F29,Backlog!$J$5:$J$219) | K29: =COUNTIFS(Backlog!$B$5:$B$219,$F29,Backlog!$E$5:$E$219,"Closed") | L29: =IFERROR($K29/$I29,0)
A30: Blocked | B30: =COUNTIF(Backlog!$E$5:$E$219,$A30) | C30: =IFERROR($B30/COUNTA(Backlog!$A$5:$A$219),0) | D30: =SUMIF(Backlog!$E$5:$E$219,$A30,Backlog!$J$5:$J$219) | F30: TOTAL | I30: =SUM(I6:I29) | J30: =SUM(J6:J29) | K30: =SUM(K6:K29) | L30: =IFERROR(K30/I30,0)
A31: On Hold | B31: =COUNTIF(Backlog!$E$5:$E$219,$A31) | C31: =IFERROR($B31/COUNTA(Backlog!$A$5:$A$219),0) | D31: =SUMIF(Backlog!$E$5:$E$219,$A31,Backlog!$J$5:$J$219)
A32: TOTAL | B32: =SUM(B18:B31) | C32: =SUM(C18:C31) | D32: =SUM(D18:D31)
A34: BY PRIORITY
A35: Priority | B35: Stories | C35: Est. days | D35: Closed
A36: P0 | B36: =COUNTIF(Backlog!$F$5:$F$219,$A36) | C36: =SUMIF(Backlog!$F$5:$F$219,$A36,Backlog!$J$5:$J$219) | D36: =COUNTIFS(Backlog!$F$5:$F$219,$A36,Backlog!$E$5:$E$219,"Closed")
A37: P1 | B37: =COUNTIF(Backlog!$F$5:$F$219,$A37) | C37: =SUMIF(Backlog!$F$5:$F$219,$A37,Backlog!$J$5:$J$219) | D37: =COUNTIFS(Backlog!$F$5:$F$219,$A37,Backlog!$E$5:$E$219,"Closed")
A38: P2 | B38: =COUNTIF(Backlog!$F$5:$F$219,$A38) | C38: =SUMIF(Backlog!$F$5:$F$219,$A38,Backlog!$J$5:$J$219) | D38: =COUNTIFS(Backlog!$F$5:$F$219,$A38,Backlog!$E$5:$E$219,"Closed")
A39: P3 | B39: =COUNTIF(Backlog!$F$5:$F$219,$A39) | C39: =SUMIF(Backlog!$F$5:$F$219,$A39,Backlog!$J$5:$J$219) | D39: =COUNTIFS(Backlog!$F$5:$F$219,$A39,Backlog!$E$5:$E$219,"Closed")
A41: BY RISK
A42: Risk | B42: Stories | C42: Est. days | D42: Closed
A43: Safety-critical | B43: =COUNTIF(Backlog!$H$5:$H$219,$A43) | C43: =SUMIF(Backlog!$H$5:$H$219,$A43,Backlog!$J$5:$J$219) | D43: =COUNTIFS(Backlog!$H$5:$H$219,$A43,Backlog!$E$5:$E$219,"Closed")
...

Sheet Backlog
A1: DEVELOPMENT BACKLOG — User Stories & Tasks
A2: Source: BACKLOG.md · 189 stories across 24 epics · Set Status from the dropdown in column E. Yellow-tinted columns (M–Q, W) are yours to fill in. Tasks/Acceptance are wrapped — widen a row or click a cell to read the full text.
A4: Story ID | B4: Epic | C4: Epic Name | D4: Story Title | E4: Status | F4: Priority | G4: Phase | H4: Risk | I4: Type | J4: Est. Days | K4: Dependencies | L4: Blocked By | M4: Owner | N4: Sprint | O4: Start Date | P4: Target Date | Q4: % Complete | R4: Task Count | S4: User Story | T4: Tasks | U4: Acceptance Criteria | V4: Notes | W4: Comments | X4: Build Concerns
A5: E00-S01 | B5: E00 | C5: FOUNDATION | D5: Project scaffold, packaging, tooling | E5: Closed | F5: P0 | G5: 0 | H5: Low | I5: INFRA | R5: 0
A6: E00-S02 | B6: E00 | C6: FOUNDATION | D6: Domain models with Decimal money and tz-aware UTC | E6: Closed | F6: P0 | G6: 0 | H6: Correctness-critical | I6: INFRA | R6: 0
A7: E00-S03 | B7: E00 | C7: FOUNDATION | D7: Config validation with hard bounds in code | E7: Closed | F7: P0 | G7: 0 | H7: Safety-critical | I7: INFRA | R7: 0
A8: E00-S04 | B8: E00 | C8: FOUNDATION | D8: Secrets handling that cannot render | E8: Closed | F8: P0 | G8: 0 | H8: Safety-critical | I8: INFRA | R8: 0
A9: E00-S05 | B9: E00 | C9: FOUNDATION | D9: Structured logging with mandatory redaction | E9: Closed | F9: P0 | G9: 0 | H9: Safety-critical | I9: INFRA | R9: 0
A10: E00-S06 | B10: E00 | C10: FOUNDATION | D10: NSE calendar with per-stock square-off | E10: Closed | F10: P0 | G10: 0 | H10: Safety-critical | I10: INFRA | R10: 0
A11: E00-S07 | B11: E00 | C11: FOUNDATION | D11: Broker protocol, read-only vs trading split | E11: Closed | F11: P0 | G11: 0 | H11: Safety-critical | I11: INFRA | R11: 0
A12: E00-S08 | B12: E00 | C12: FOUNDATION | D12: Strategy DSL with vetted primitive registry | E12: Closed | F12: P0 | G12: 0 | H12: Safety-critical | I12: INFRA | R12: 0
A13: E00-S09 | B13: E00 | C13: FOUNDATION | D13: Docker topology with network segmentation | E13: Closed | F13: P0 | G13: 0 | H13: Correctness-critical | I13: INFRA | R13: 0 | V13: written, not run
A14: E00-S10 | B14: E00 | C14: FOUNDATION | D14: Pre-flight doctor script | E14: Closed | F14: P0 | G14: 0 | H14: Low | I14: INFRA | R14: 0
A15: E01-S01 | B15: E01 | C15: PERSISTENCE & DATA LAYER | D15: Database schema and migrations | E15: Closed | F15: P0 | G15: 1 | H15: Correctness-critical | I15: INFRA | J15: 2 | K15: none | N15: 1 | Q15: 100 | R15: 9 | S15: As a developer, I want the full database schema defined as versioned migrations, so that schema changes are reviewable and reversible rather than applied by hand. | T15: 1. Set up Alembic with async SQLAlchemy 2.0 2. SQLAlchemy models mirroring LOW_LEVEL_ARCHITECTURE §4.2 3. Migration: instruments, instrument_daily_status 4. Migration: ohlcv as a TimescaleDB hypertable 5. Migration: orders, positions, decision_log, trade_journal 6. Migration: daily_plan, plan_candidate 7. Migration: strategy, strategy_validation, strategy_trial, strategy_performance, shadow_signal 8. Compression policy on ohlcv (>90 days) 9. `make migrate` target | U15: • `alembic upgrade head` then `downgrade base` runs clean on an empty DB • Hypertables confirmed via `SELECT * FROM timescaledb_information.hypertables` • `decision_log` and `strategy_trial` roles have INSERT but not UPDATE/DELETE | V15: CLOSED 7 Aug 2026. Schema, migrations and role grants complete; 38 integration tests assert every business rule against a real TimescaleDB. DELIVERED: 15 tables in common/db/models.py; two migrations (core schema autogenerated, hypertables/view/grants hand-written); upgrade head -> downgrade base -> upgrade head verified clean. DECISIONS TAKEN: - TimescaleDB DDL is VERSION-ADAPTIVE. The migration detects the installed version and emits columnstore DDL at >=2.18 or legacy compression below it. Verified on BOTH 2.17.2 and 2.29.1, so the pin decision no longer blocks anything and can move either way later. - Role created NOLOGIN/password-less; operator grants LOGIN out of band. The spec's CREATE ROLE ... PASSWORD would have committed a credential. - v_eligible_today anchored to Asia/Kolkata, not CURRENT_DATE. FOUR BUGS FOUND BY EXECUTION (all fixed, all now covered by tests): 1. SQLAlchemy Enum(native_enum=False) defaults create_constraint=FALSE since 1.4 — the enum columns had NO validation at all. An invalid 'side' went straight in. Only the column length was accidentally guarding them. 2. decision_log.id was NOT NULL with no sequence: SQLAlchemy attaches an implicit sequence only to a PRIMARY KEY, and this is not one. EVERY insert failed. Fixed with an explicit Identity(). 3. order_fills generated-column DDL in the spec was invalid PostgreSQL. 4. Enum columns sized to an exact fit meant truncation errors fired before CHECK constraints, producing an error naming neither column nor expected value. NOT a bug but worth knowing: autogenerate cannot render ORM attributes in postgresql_where; partial index predicates use sa.text(). | W15: Open questions to settle inside this story (§17): Q1 RESOLVED — pin is 2.17.2-pg16; upgrade decision is yours, recommended. Q2 Retention of 1m bars — recommend keep forever; ~19M rows either way, storage is not the constraint, backtest depth is. Q3 DB roles — recommend one app role now, split per-service at Phase 7. Q4 Audit buffer location — recommend host mount (survives image rebuild). Watch: TimescaleDB requires the partitioning column in every unique index; downgrade must drop policies before hypertables; test 'downgrade base' on every migration.
A16: E01-S02 | B16: E01 | C16: PERSISTENCE & DATA LAYER | D16: Repository layer | E16: Closed | F16: P0 | G16: 1 | H16: Low | I16: INFRA | J16: 2 | K16: E01-S01 | N16: 1 | Q16: 100 | R16: 5 | S16: As a developer, I want data access behind repository interfaces, so that services never write raw SQL and can be tested against fakes. | T16: 1. `Repository` protocol per aggregate (instruments, bars, orders, positions, plan, strategy) 2. Async session management with proper transaction boundaries 3. Bulk insert path for OHLCV (batched, not row-by-row) 4. Connection pooling configured 5. In-memory fakes for unit tests | U16: • No service module imports `sqlalchemy` directly • Bulk insert of 100k bars completes in < 10s | V16: CLOSED 7 Aug 2026. Repository layer complete; 25 integration tests, both acceptance criteria measured rather than asserted. DELIVERED: common/db/engine.py (async engine, session factory, unit_of_work / read_only boundaries) and common/db/repositories.py (Instrument, Bar, DailyStatus, Order, Position, DecisionLog-read repositories plus Protocols). THE ARCHITECTURE THIS STORY OWNS — the symbol <-> symbol_id impedance mismatch (spec §2.3 E). Domain models address instruments by ticker; every table uses an integer FK. InstrumentRepository holds a bidirectional cache and is the ONLY component permitted to translate. Proven: 50 lookups issue 0 queries. THREE REAL BUGS FOUND BY EXECUTION: 1. POSTGRESQL CAPS BOUND PARAMETERS AT 65535. A bar has up to 12 columns, so the spec's "one TX per batch of ~10k" sends ~120,000 parameters and fails outright with "number of parameters must be between 0 and 65535". This would have surfaced during the 24-MILLION-row historical backfill, not in any unit test. bulk_upsert now chunks INTERNALLY against the parameter limit, sized off the WIDEST row (sizing off the first row under-counts when callers omit optional columns), so no caller can hit it. 2. Chunked multi-row INSERT was correct but SLOW — 100k bars in 23.8s against a 10s budget. Implemented the spec's COPY path (task 3): COPY into a temp table, then one set-based INSERT ... SELECT ... ON CONFLICT DO UPDATE. Now inside budget. COPY cannot express ON CONFLICT itself, which is why the temp table exists. 3. The COPY path needed CREATE TEMP TABLE IF NOT EXISTS + TRUNCATE, not a bare CREATE. ON COMMIT DROP only fires at COMMIT, so the SECOND chunk of a backfill inside one transaction failed with "relation _bar_load already exists". Also: DISTINCT ON (symbol_id, timeframe, ts) ORDER BY ... ctid DESC in the COPY upsert. ON CONFLICT raises "cannot affect row a second time" when the SOURCE holds duplicate keys, which a batch spanning a reconnect legitimately does. Last occurrence wins, matching the INSERT path. Also: the Windows ProactorEventLoop defect RESURFACED in pytest-asyncio. configure_event_loop_policy() must run BEFORE the loop is created; calling it inside create_engine was too late because pytest-asyncio had already built one. Now called at tests/conftest.py import time. Lesson recorded: every async entry point owns that responsibility separately. DESIGN DECISIONS AND WHY: - Repositories return plain dicts, never ORM instances. An ORM object carries session affinity and lazy loaders; once its session closes, touching an unloaded attribute raises MissingGreenlet deep inside business logic. A dict cannot. - warm_up_batch is ONE query with a window function. A per-symbol loop is correct and passes every other test, then misses the 45-minute BP-2 deadline with 450 round trips. The test asserts the QUERY COUNT is constant regardless of symbol count, so that refactor fails here rather than at 08:45 on a trading morning. - expire_on_commit=False: the default makes every attribute a fresh SELECT after commit, and in async code that lazy load raises MissingGreenlet rather than merely being slow. - Server-side statement_timeout, not a client-side cancel. A client-side timeout abandons the query while the server keeps executing it. - read_only() rolls back rather than commits — releases the snapshot immediately, so a long idle-in-transaction session cannot hold back vacuum across the database. - ON CONFLICT DO UPDATE, not DO NOTHING: a late trade report legitimately revises volume and vwap, and a corporate action re-adjusts prices. DO NOTHING would silently pin stale data. - UnknownSymbolError raises rather than returning None. Silently skipping an unknown symbol loses market data with NO error; the gap surfaces days later as an indicator that never warms up. SECURITY: the COPY path builds SQL identifiers by f-string because PostgreSQL cannot parameterise identifiers. Every interpolated value comes from a fixed tuple in the function and is unreachable from market data, news or any request. Justified in place with a noqa so it does not need re-deriving at review time; all VALUES still go through COPY's binary protocol or bound parameters.
A17: E01-S03 | B17: E01 | C17: PERSISTENCE & DATA LAYER | D17: Redis client and keyspace helpers | E17: Closed | F17: P0 | G17: 1 | H17: Correctness-critical | I17: INFRA | J17: 1.5 | K17: none | N17: 1 | Q17: 100 | R17: 6 | S17: As a developer, I want typed helpers for the Redis keyspace, so that key naming cannot drift between services. | T17: 1. Async Redis client with connection pooling and retry 2. Key builders for every pattern in LOW_LEVEL_ARCHITECTURE §4.3 3. Typed get/set for state hashes (Pydantic in, Pydantic out) 4. Distributed lock helper with mandatory TTL 5. Token bucket rate limiter 6. Sorted-set timer helper | U17: • Every key in the design doc has a builder function • A lock without a TTL is impossible to create (TTL is a required arg) | V17: CLOSED 7 Aug 2026. Redis layer complete; 35 integration tests, all probing real behaviour against a real Redis. DELIVERED: common/redis/ — keys.py (23 key builders, no literal permitted elsewhere), client.py (pool, retry, health), locks.py (mandatory TTL), primitives.py (token bucket + timer ZSET, both Lua), state.py (typed Pydantic accessors). THE STORY'S REAL CONTENT — ttl_ms is a REQUIRED positional argument with no default. A lock without a TTL survives the death of the process holding it and deadlocks slot allocation for the rest of the session, silently. Also bounded above (MAX_TTL_MS 300s) to catch seconds-passed-as-milliseconds, which is the realistic mistake. DESIGN DECISIONS AND WHY: - Release/extend are compare-and-delete in Lua. The naive get-then-delete is a race: the lock can expire between check and delete, be re-acquired by another process, and you then delete THEIR lock. - Token bucket and pop-due are Lua for the same reason. A Python-side get/compute/set lets two callers see the same token count and both proceed — for the order limiter that means breaching the broker cap and, above 10/sec, the SEBI threshold. Proven by a 25-way concurrent test that must yield exactly capacity. - decode_responses=True is load-bearing, not cosmetic. Without it every read is bytes and b"1" != "1", so a kill-switch check silently reads as "not set" and trading continues. - Invalid stored state is treated as ABSENT, not raised. Half-valid trading state is worse than none because the system keeps acting on it; absent routes into the existing fail-closed path (no indicators -> no signal). Logged loudly. - is_kill_switch_active FAILS CLOSED — an unreachable Redis returns True (halted). A false halt costs a trade; a false all-clear costs an uncontrolled position. Tested against a dead endpoint. - assert_noeviction() refuses to start if Redis is not noeviction, because under any eviction policy Redis silently discards positions or the kill switch with no error at the point of loss. ISSUES FOUND AND FIXED DURING THE BUILD: 1. bandit S105 false-positived on _TOKEN_BUCKET_LUA (matches "token" in the identifier). A noqa CANNOT go on that line — it ends by opening a triple-quoted string, so the comment becomes Lua source, and # is not a comment in Lua, which silently corrupts the script. Renamed the constant instead. 2. Package named common/redis shadows the library by name; verified safe because Python 3 uses absolute imports. Documented in __init__. NOT DONE HERE: stream helpers live in E01-S04; keys.py already provides their key builders.
A18: E01-S04 | B18: E01 | C18: PERSISTENCE & DATA LAYER | D18: Event stream abstraction | E18: Closed | F18: P0 | G18: 1 | H18: Correctness-critical | I18: INFRA | J18: 1.5 | K18: E01-S03 | N18: 1 | Q18: 100 | R18: 6 | S18: As a developer, I want a typed wrapper over Redis Streams with consumer groups, so that no event is lost when a consumer restarts. | T18: 1. `EventStream` publish/subscribe with Pydantic envelopes 2. Consumer group creation and management 3. Explicit acknowledgement 4. Pending-entry recovery on restart 5. Dead-letter handling after N failures 6. `schema_version` on every envelope | U18: • Kill a consumer mid-stream; on restart it processes the unacked backlog • Messages published while a consumer is down are delivered on return | V18: CLOSED 7 Aug 2026. Event stream layer complete; 27 integration tests including the epic's headline acceptance criterion. DELIVERED: common/events/ — envelope.py (versioned, immutable, correlation-carrying) and stream.py (publish, consumer groups, backlog recovery, reclaim, dead-letter). THE STORY'S REAL CONTENT — maxlen is a REQUIRED keyword argument on publish(), with no default. Redis runs maxmemory 2gb + noeviction. That policy is right (trading state must never be silently evicted) but it means an untrimmed stream does NOT drop old entries — it fills memory and Redis then REFUSES ALL WRITES, system-wide, mid-session. stream:ticks alone is ~10 MB/day. A stream publishable without a bound should not be constructible, and now is not. ACCEPTANCE CRITERION PROVEN: test_crash_mid_stream_loses_nothing — publish 100, consume+ack 50, strand 10 unacked (the crash), restart, assert all 100 processed and pending == 0. This catches the single easiest mistake in the component: on restart a consumer MUST read its own pending backlog at id '0' first. A '>' read returns only NEW messages, so every entry in flight at the moment of a crash is invisible and stranded forever. Backlog is also drained BEFORE new messages, since taking new work ahead of older unacked work reorders the stream from the consumer's view. DESIGN DECISIONS AND WHY: - At-least-once delivery, consumers idempotent. Correct rather than a limitation: a bar processed twice yields the same indicator state; a duplicate signal is caught by lock:symbol and uq_open_symbol; a duplicate audit event by message_id. Exactly-once would need distributed transactions across Redis and Postgres for no practical gain. - Approximate trimming (MAXLEN ~). The property needed is "bounded", not "exactly N"; exact trimming is materially more expensive. The test asserts boundedness, not equality, so it does not encode a Redis implementation detail. - Dead-letter writes to the DLQ BEFORE acking the original. If the process dies between the two the entry stays pending and is retried — recoverable. Acking first would lose it outright. - A malformed entry is logged and SKIPPED, never raised out of the read loop. One poisoned message must not stop the stream. Envelope.from_fields raises ValueError specifically so consumers can catch a narrow type to dead-letter. - schema_version present from message one — retrofitting it onto streams that already hold unversioned entries means writing a shim that guesses. - Consumer names carry a uuid suffix. Two processes sharing a name share a pending list, so one can acknowledge the other's in-flight work. - Payload is nested JSON in ONE stream field, not spread across fields. Redis stream fields are a flat string map; flattening would lose type information exactly where Decimal matters. ISSUE FOUND AND FIXED: redis-py types the xadd field map as an invariant dict of bytes|str|int|float; dict[str, str] is a valid subset but mypy will not narrow it. Cast with the reason recorded in place rather than loosening the function signature.
A19: E01-S05 | B19: E01 | C19: PERSISTENCE & DATA LAYER | D19: Audit log writer with hash chaining | E19: Closed | F19: P0 | G19: 1 | H19: Safety-critical | I19: SEC | J19: 1 | K19: E01-S01 | N19: 1 | Q19: 100 | R19: 5 | S19: As an operator, I want every decision written to an append-only hash-chained log, so that tampering is detectable and I can substantiate any trade. | T19: 1. `AuditWriter` — append-only, never updates 2. Hash chain: each row includes the previous row's hash 3. `correlation_id` on every entry 4. Chain verification utility 5. Buffer to disk if the DB is unavailable, replay on recovery | U19: • Modifying a historical row is detected by the verifier • DB outage does not lose audit entries | V19: CLOSED 7 Aug 2026. SAFETY-CRITICAL (red) — the strict DoD was met in full and NOT relaxed by the reprioritisation. 30 tests: property-based over generated sequences, explicit tamper tests, explicit outage tests, and a concurrency test. DELIVERED: common/audit.py — canonical_json, compute_row_hash, AuditEntry, AuditWriter (with disk buffer), verify_chain. THREE PROPERTIES, EACH ENFORCED STRUCTURALLY: 1. Cannot be modified or deleted — the app role has INSERT but no UPDATE/DELETE (E01-S01 grants). Append-only by convention is a promise; by a missing grant it is a guarantee. 2. Tampering is DETECTABLE even by someone who bypasses the grants. Each row hashes its predecessor's hash, so altering any historical row invalidates every hash after it. Tested: a modified payload, a flipped REJECT->ALLOW, a deleted row, and — the important one — a LOCALLY CONSISTENT FORGERY where the attacker recomputes that row's own hash. It still breaks, at the NEXT row. Hiding a change requires recomputing the entire remaining chain. 3. Survives the DB being down. Entries buffer to disk (fsync per line) and replay in order on recovery; the chain is computed at replay time because a buffered entry's position is not knowable while the DB is down. DESIGN DECISIONS AND WHY: - AuditWriter takes a session FACTORY, never a session. An audit entry written inside a business transaction VANISHES when that transaction rolls back — and a failed attempt is often exactly what you need to investigate. Making it a factory means sharing a transaction is impossible, not merely discouraged. - pg_advisory_xact_lock, taken BEFORE reading the chain head. Read-then-lock lets two writers observe the same prev_hash and fork the chain — and a forked chain fails verification with no tampering having occurred. Transaction-scoped so a crashed writer cannot leak the lock. Proven by a 20-write concurrent test asserting one valid chain with contiguous seq. - write() NEVER raises on a DB failure. An audit write that killed the caller would mean a database blip stops trading AND loses the record of why. - canonical_json with sort_keys: Python dicts are insertion-ordered, so the same logical payload built by two code paths would hash differently and fail verification for no reason. - Timestamps normalised to UTC before hashing, so a row hashed in one timezone verifies in another. Naive timestamps are refused outright. - GLOBAL chain, not per-correlation_id. The per-correlation alternative is simpler and lock-free but CANNOT detect deletion of an entire trade's worth of entries — precisely the tampering worth defending against. Tested. - A failed replay KEEPS the buffer file for retry. Deleting first and failing after would lose entries permanently; retrying at worst duplicates, which is recoverable. ISSUE FOUND AND FIXED: create_engine_from_url had no connect timeout, so the outage tests pointed at a dead endpoint HUNG the suite on the OS TCP timeout (minutes). Added connect_timeout, defaulting to 10s. This is a production concern too, not just a test one: without it "the database is down" presents as "the process appears to hang", which is a far worse failure to diagnose at 09:15. SECURITY: verify_chain originally interpolated its WHERE clause and needed an S608 suppression that kept drifting as the formatter reflowed the string. Rewritten as a four-entry lookup table of complete literal queries — no interpolation at all, so there is no injection surface to justify rather than a justified one. Better answer than a noqa. | X19: The hash chain cannot detect TRUNCATION. Deleting the last N rows leaves a perfectly valid chain — verification passes. The append-only GRANT is the real control there and it is tested, but if you ever need tamper-evidence against someone with DB owner rights, that needs an external anchor (periodically publishing the tip hash somewhere the DB cannot reach). Decide whether that is in scope before relying on the chain for a compliance claim.
A20: E01-S06 | B20: E01 | C20: PERSISTENCE & DATA LAYER | D20: Data retention and archival | E20: Closed | F20: P2 | G20: 6 | H20: Low | I20: OPS | J20: 0.5 | K20: E01-S01 | N20: 16 | Q20: 100 | R20: 3 | S20: As an operator, I want old tick data archived to Parquet, so that the database stays small without losing replay capability. | T20: 1. Nightly job: ticks older than 24h → Parquet 2. Compression policy verification 3. Restore-from-archive utility | V20: CLOSED 7 Aug 2026. Retention, archival and restore complete; 16 integration tests. This was P2/Phase 6 and originally scheduled for Sprint 16 — built now because the direction is to complete every E01 item and it has no blocker. DELIVERED: common/db/retention.py — archive_bars, read_archive, restore_bars, purge_archived_bars, compression_status. THE SAFETY PROPERTY THIS STORY IS REALLY ABOUT — market data CANNOT BE RE-DERIVED. A gap is permanent and silently corrupts every future backtest over that window. So: - archive_bars WRITES AND READS BACK, comparing row counts, before returning. A write that reports success having produced a truncated file is exactly the failure an archive must not have, and it is only detectable by reading. - Nothing in archive_bars deletes. purge_archived_bars is a SEPARATE call that re-reads the archive and refuses unless it holds at least as many rows as the database does for that range. Both refusals are tested, each paired with a control proving the refusal is targeted rather than blanket. - An EMPTY range is refused outright. An empty archive would later look like a verified archive of nothing and could authorise a purge of data it never held. - The full cycle is tested: archive -> purge -> restore -> prices still exact. An archive nobody has restored from is a hypothesis, not a backup. DESIGN DECISIONS AND WHY: - Decimals are archived as STRINGS, not floats. A float round trip loses exactness and would silently corrupt every archived price — the one thing this file exists to preserve faithfully. Asserted directly. - Parquet over CSV: columnar, ~10x compression on this shape, preserves types, and readable by pandas/DuckDB/Polars with no loader. CSV would turn every Decimal into a string and every timestamp into an ambiguous one. - restore uses ON CONFLICT DO NOTHING, not DO UPDATE. The archive is older by definition, so the live copy is authoritative; a restore that overwrote would roll back corrections that arrived after the archive was taken. Tested. - compression_status treats ZERO compressed chunks as HEALTHY on a young database — nothing is 90 days old yet. What matters is that the policy is scheduled and its last run did not fail. A policy that silently stops converting produces no error at all; the first symptom is the disk filling weeks later. DEPENDENCY DECISION (procedure §8.2 — a decision, not a blocker): pyarrow was not installed or declared. Added as a main dependency at >=18.0 (installed 25.0.0). It is large (~100 MB) but is the standard implementation and the archive job runs in the same deployment as everything else. Also added to the mypy ignore_missing_imports overrides, since it ships no stubs.
A21: E01-S07 | B21: E01 | C21: PERSISTENCE & DATA LAYER | D21: Datastore scaffolding and Alembic bootstrap | E21: Closed | F21: P0 | G21: 1 | H21: Correctness-critical | I21: INFRA | J21: 1 | K21: none | L21: None | M21: None | N21: 1 | O21: None | P21: None | Q21: 100 | R21: 6 | S21: As a developer, I want the database/Redis configuration, the Alembic environment and the container test fixtures to exist, so that E01-S01 can start writing migrations instead of first building the ground they run on. | T21: 1. DatabaseConfig + RedisConfig in common/config.py; database:/redis: sections in system.yaml 2. alembic.ini + migrations/env.py wired to load_config(), with the TimescaleDB chunk filter on autogenerate 3. common/db/base.py — DeclarativeBase + constraint naming convention 4. common/db/eventloop.py — Windows ProactorEventLoop fix for async psycopg 5. .env.example credential split; docker-compose DATABASE_URL/REDIS_URL injection; Makefile --env-file fix 6. tests/conftest.py container fixtures + 6 scaffold integration tests | U21: • `alembic upgrade head` runs (and fails with a helpful message when no password is configured) • Container fixtures start TimescaleDB + Redis and SKIP rather than fail when Docker is down • `doctor` reports which datastore config source is in effect • Test container image is read from docker-compose so it cannot drift • Full suite green | V21: CLOSED — completed 7 Aug 2026, ahead of E01-S01. Added retrospectively: this work was NOT in the backlog, but E01-S01 task 1 assumed all of it existed. Recording it so the 2-day E01-S01 estimate is not silently carrying another day of work. FOUR BLOCKERS FOUND BY EXECUTION, each of which would have stopped E01-S01 on day one: 1. async psycopg refuses Windows' default ProactorEventLoop — `make migrate` failed outright with InterfaceError. Invisible on Linux/macOS, so CI would never have caught it. 2. `make up` never passed compose an --env-file, so it failed even with a correct .env. 3. GRAFANA_PASSWORD required by compose but missing from .env.example. 4. `make` is not installed on this machine at all. Result: 118 tests passing (112 + 6 new). See Code/SETUP.md. | W21: Verified empirically rather than from docs: • TimescaleDB 2.17.2 has add_compression_policy only; 2.29.1 has BOTH that and add_columnstore_policy — so the pin upgrade is backward compatible. Registry says 2.29.1 is current (a web source claiming 2.20.2 was stale). • TA-Lib resolved to a prebuilt Windows wheel (0.7.1) — NOT the install blocker it appeared to be. • testcontainers: .postgres/.redis import paths are deprecated (use .community.*), and PostgresContainer defaults to driver='psycopg2' which this project does not install.
A22: E01-S08 | B22: E01 | C22: PERSISTENCE & DATA LAYER | D22: Clear lint debt so `make check` can gate merges | E22: Closed | F22: P1 | G22: 1 | H22: Low | I22: INFRA | J22: 0.5 | K22: none | L22: None | M22: None | N22: 1 | O22: None | P22: None | Q22: 100 | R22: 4 | S22: As a developer, I want `make check` to exit 0 on a clean tree, so that it can be used as a merge gate for E01 instead of being a command everyone knows is already red. | T22: 1. `ruff check --fix .` — clears 14 of 30 automatically 2. `ruff format .` 3. Fix the remainder by hand: line length, ambiguous Unicode in docstrings, unused noqa directives, one assert_raises_exception, one hardcoded-password-string (test fixture — confirm it is a false positive before silencing) 4. Confirm `make check` exits 0, then treat any future failure as a genuine regression | U22: • `ruff check .` reports no errors • `ruff format --check .` reports no changes needed • `make check` (lint + types + tests) exits 0 • No test is deleted or skipped to achieve the above | V22: CLOSED 7 Aug 2026. `make check` (lint + types + tests) now exits 0 — the merge gate works. Was 28 ruff errors + 1 mypy error. Auto-fix cleared 12; the rest were fixed individually: an S105 false positive on an auth-method NAME, RUF012 needing ClassVar, RUF043 needing a raw regex, B017 blind pytest.raises(Exception) narrowed to ValidationError, __all__ sorted, one stale type: ignore removed. CONFIG DECISION: RUF001/002/003 confusables are configured via allowed-confusables rather than mangled. En dashes, ≤/≥ and ₹ are deliberate typography throughout the docs; rewriting them to ASCII would make the documentation worse. Anything NOT on the allowlist is still flagged, so a Cyrillic homoglyph in an identifier is still caught. Done FIRST rather than last (the story originally said 'before E01-S01 merges'): a green gate from day one benefits every story after it. | W22: Sequence before E01-S01 merges, not before it starts — the two are independent and this one needs no design decisions. Half a day is generous; most of it is one command.
A23: E02-S01 | B23: E02 | C23: BROKER INTEGRATION | D23: Kite Connect authentication — redirect flow | E23: Development Completed | F23: P0 | G23: 1 | H23: Safety-critical | I23: SEC | J23: 2 | K23: none | Q23: 0.9 | R23: 7 | S23: As a trader, I want the daily Zerodha login to complete through a link I tap on my phone, so that the system has a valid session before pre-open without me sitting at a laptop. | T23: 1. Generate the Kite login URL with `api_key` 2. Local callback endpoint receiving `request_token` 3. Exchange `request_token` + `api_secret` → `access_token` 4. Store token as `SecretString` in Redis with TTL to next pre-open 5. Send the login link via Telegram at the configured time 6. Confirm success back to Telegram 7. Alert loudly on failure — this blocks the trading day | U23: • Full flow completes from a phone in under 60 seconds • Token never appears in any log • Expired token is detected before the pre-market job starts | V23: Auth manager, session lifecycle, login-URL builder AND the client factory are built and tested. session.py now completes the redirect login: build_client() and exchange_request_token(). The raw token is revealed at exactly two points, both handing it straight to the SDK, with a test that fails if a third appears. SECURITY: the re-auth notice carries NO login link - ReauthNotice has no url field at all, so the phishing reflex cannot be reintroduced by a later edit. The api_key is validated before it reaches the login URL (QA-SEC-15): unvalidated, an injected redirect_uri steers your request_token to an attacker while you are on a genuine Zerodha page. Remaining 10%: verifying the exchange against a live request_token, and the callback endpoint - which is the same network decision as E17-S01's dashboard access (localhost vs phone). Decide them together. | X23: TWO issues. (1) Task 5 sends a login link over Telegram, which trains you to authenticate from an inbound message — the consent-phishing pattern. Anyone who can post one message (leaked bot token, SIM-swapped Telegram, lookalike bot) sends a link to THEIR Kite app at the time you expect it; you authenticate on a genuine Zerodha page and hand them a request_token they exchange with their own api_secret. 2FA does not help — you are authorising the wrong app, not leaking a password. Server-side nonce checks cannot help either: the attack completes entirely outside your system. FIX: send a notification with NO link; open the dashboard from your own bookmark. (2) Task 2 says 'local callback endpoint' but acceptance says 'completes from a phone'. A phone cannot reach 127.0.0.1 on the server. Either the callback is publicly reachable over HTTPS — which puts an inbound endpoint on the box holding broker credentials, against the internal-network design — or the flow completes on the server host. Decide before building.
A24: E02-S02 | B24: E02 | C24: BROKER INTEGRATION | D24: Session lifecycle and daily re-auth scheduling | E24: Development Completed | F24: P0 | G24: 1 | H24: Safety-critical | I24: SEC | J24: 1 | K24: E02-S01 | Q24: 0.7 | R24: 5 | S24: As a compliance-conscious operator, I want sessions to expire and re-establish daily, so that the SEBI auto-logout requirement is met by design. | T24: 1. Scheduled trigger at `broker.auth.daily_reauth_time` 2. Session validity check before every trading-day transition 3. Retry with backoff ×3, then halt the day 4. `auth.refreshed` / `auth.failed` events 5. Health gate integration — no valid session means no trading | U24: • 20 consecutive sessions authenticate successfully • A failed auth prevents the session reaching `TRADING` | V24: Session validity, expiry-at-next-reauth and the notice hook are built and tested. Remaining: wiring the scheduled trigger and the health gate, which belong to the orchestrator rather than the broker layer.
A25: E02-S03 | B25: E02 | C25: BROKER INTEGRATION | D25: Read-only market data adapter | E25: QA-Success | F25: P0 | G25: 1 | H25: Correctness-critical | I25: FEAT | J25: 1.5 | K25: E02-S01 | Q25: 1 | R25: 4 | S25: As a developer, I want a read-only Kite adapter, so that data services physically cannot place orders. | T25: 1. Implement `MarketDataAdapter` for Kite 2. `fetch_instruments`, `fetch_historical`, quote endpoints 3. Apply `ReadOnlyGuard` so trading methods raise 4. Map Kite errors to the adapter's error taxonomy | U25: • Calling `place_order` on this adapter raises `PermissionError` • Data endpoints work from a non-whitelisted IP (verifying the order-only scope) | V25: Read-only adapter built on ReadOnlyGuard; place/modify/cancel all raise PermissionError, asserted. subscribe() deliberately raises: E05-S01 will implement the documented Kite WebSocket wire protocol rather than KiteTicker, which avoids autobahn 19.11.2 (CVE-2020-35678, blocker B7) and the Twisted reactor bridging problem in one move. Needs no static IP - Zerodha validates the whitelist on order endpoints only.
A26: E02-S04 | B26: E02 | C26: BROKER INTEGRATION | D26: Trading adapter with market protection | E26: QA-Success | F26: P0 | G26: 5 | H26: Safety-critical | I26: FEAT | J26: 2 | K26: E02-S03, E14-S01 | Q26: 1 | R26: 7 | S26: As a trader, I want orders placed correctly with market protection attached, so that MARKET and SL-M orders are not rejected by the broker. | T26: 1. Implement `TradingAdapter` for Kite 2. Attach `market_protection` on MARKET/SL-M 3. Attach Algo-ID per the confirmed mechanic (blocked on B1) 4. `place_order`, `modify_order`, `cancel_order` 5. `fetch_orderbook`, `fetch_positions`, `find_by_client_order_id` 6. Map broker errors → `OrderRejectedError` / `AmbiguousOrderError` / `RateLimitError` 7. Verify installed SDK exposes `market_protection`, fail startup if not | U26: • A MARKET order without protection is impossible to construct • A timeout raises `AmbiguousOrderError`, never a silent retry | V26: Trading adapter with market protection enforced at the boundary (missing and zero both refused). client_order_id -> Kite tag resolved: the tag is alphanumeric, max 20 chars, and IS returned in the orderbook, so broker_tag() truncates the sha256 id deterministically in one place and the submission and recovery paths are asserted to agree. Restructured so the trading adapter does NOT inherit ReadOnlyGuard - 'may trade' is stated positively rather than achieved by overriding a refusal. | X26: RESOLVED Aug 2026. Kite's tag is alphanumeric, max 20 chars, and IS returned in the orderbook - confirmed against the API docs. broker_tag() truncates the sha256 id deterministically in one place, and a test asserts the submission and recovery paths produce the same value. A non-alphanumeric id is refused rather than silently mangled. Two further defects were found here by QA and fixed: a foreign order type used to kill the whole orderbook read (QA-E02-01), and a duplicate tag used to be resolved by picking one (QA-E02-02).
A27: E02-S05 | B27: E02 | C27: BROKER INTEGRATION | D27: Order rate limiting | E27: QA-Success | F27: P0 | G27: 5 | H27: Safety-critical | I27: SEC | J27: 1 | K27: E01-S03, E02-S04 | Q27: 1 | R27: 5 | S27: As a compliance-conscious operator, I want the order rate capped in the adapter, so that no caller can breach the limit regardless of its behaviour. | T27: 1. Redis token bucket wrapping `place_order` 2. Separate bucket for data endpoints 3. Backpressure: queue with depth limit 4. Reject new signals rather than delay orders unboundedly 5. `orders_rate_limited_total` metric | U27: • A deliberate flood of 100 orders/sec results in ≤ 3/sec reaching the broker • Queue depth beyond threshold rejects rather than buffers | V27: Redis token bucket, account-wide key, orders and data on separate budgets so a backfill cannot starve an exit. Refuses rather than queues. Config refuses >= 10 orders/sec in code. FOUND A REAL DEFECT while testing this - see QA-SEC-14. | X27: RESOLVED Aug 2026, and CONFIRMED by Zerodha: ten OPS is account-specific, regardless of the number of apps. The bucket is account-scoped in Redis, orders and data have separate budgets so a backfill cannot starve an exit, and the config refuses ten or more per second in code. STILL LIVE: the budget is shared with anything else trading the account, including the Kite mobile app. Running at 3/sec against a cap of 10 leaves that headroom deliberately - but manual trading during a session eats into it.
A28: E02-S06 | B28: E02 | C28: BROKER INTEGRATION | D28: Instrument master synchronisation | E28: QA-Success | F28: P0 | G28: 1 | H28: Correctness-critical | I28: FEAT | J28: 1 | K28: E01-S02, E02-S03 | Q28: 1 | R28: 4 | S28: As a system, I need the current instrument master, so that symbols map to broker tokens, lot sizes and tick sizes correctly. | T28: 1. Daily fetch of the instrument dump 2. Upsert into `instruments` 3. Detect and log symbol changes, delistings, new listings 4. Tick-size rounding helper verified against real instruments | U28: • A limit price is always snapped to a valid tick before submission | V28: Instrument sync with new-listing and delisting detection, and an implausibility check so a truncated download is loud rather than silently shrinking the universe. Side-aware tick rounding added: buy rounds down, sell rounds up, so neither side ever pays more than intended. | X28: RESOLVED Aug 2026, and it was worse than this concern described. Side-aware rounding was written and tested (buy down, sell up, so neither side pays more than intended) - and then never called in the order path. The BA pass caught it: E02-S06's acceptance criterion says a limit price is ALWAYS snapped, and ATR-derived stops are essentially never on a 0.05 grid, so the exchange would have rejected every computed stop. Now snapped at the boundary, trigger prices too, failing CLOSED when no tick resolver is wired.
A29: E02-S07 | B29: E02 | C29: BROKER INTEGRATION | D29: Live margin retrieval | E29: QA-Success | F29: P0 | G29: 5 | H29: Safety-critical | I29: FEAT | J29: 0.5 | K29: E02-S04 | Q29: 1 | R29: 3 | S29: As a risk engine, I need real available margin from the broker, so that sizing never assumes leverage that SEBI peak-margin rules do not permit. | T29: 1. `fetch_margins` returning `MarginSnapshot` 2. Cache with a short TTL (margin moves during the session) 3. Staleness guard — reject sizing on stale margin data | U29: • Sizing uses live margin, never a computed leverage multiple | V29: Live margin plus a staleness bound. margin_for_sizing() refuses a snapshot older than the TTL, which closes the time-of-check/time-of-use gap - margin falls after every fill, so a stale reading can authorise a position the account cannot carry. | X29: RESOLVED Aug 2026. margin_for_sizing() refuses a snapshot older than the TTL, closing the time-of-check/time-of-use gap - margin falls after every fill, so a stale reading can authorise a position the account cannot carry. NOTE the bound is on AGE, not on change. Re-fetching after each fill is the caller's responsibility and belongs with E14-S06.
A30: E02-S08 | B30: E02 | C30: BROKER INTEGRATION | D30: Fallback broker adapter (Fyers) | E30: New | F30: P2 | G30: 2 | H30: Low | I30: FEAT | J30: 2 | K30: E02-S03 | R30: 3 | S30: As an operator, I want a second data source, so that a Zerodha WebSocket outage at the open does not blind the system. | T30: 1. Fyers auth and read-only adapter 2. Failover logic on primary feed staleness 3. Cross-source price divergence detection | V30: DEFERRED, not blocked. Fyers fallback is the only Low-risk story in E02 and adds a second broker SDK plus a second auth flow. Worth doing once the primary path has run against live data, so the fallback is written against known behaviour rather than assumptions.
A31: E02-S09 | B31: E02 | C31: BROKER INTEGRATION | D31: Broker error taxonomy handling | E31: QA-Success | F31: P0 | G31: 5 | H31: Safety-critical | I31: FEAT | J31: 1 | K31: E02-S04 | Q31: 1 | R31: 5 | S31: As a system, I want every broker failure classified correctly, so that an ambiguous outcome never results in a duplicate order. | T31: 1. Map every Kite error code to the taxonomy 2. `AmbiguousOrderError` → query-by-`client_order_id` recovery path 3. Never retry on `OrderRejectedError` 4. Exponential backoff on `RateLimitError` 5. Log every unmapped error code loudly for triage | U31: • Simulated timeout + reconnect produces exactly one position (chaos test) | V31: Error taxonomy with the safety switch: classify(mutating=True) makes any UNRECOGNISED failure AmbiguousOrderError, routing to query-by-tag rather than retry. Only a 429 is retryable. Verified by mutation testing - breaking the fail-closed rule fails the test. | X31: RESOLVED Aug 2026. classify(mutating=True) makes ANY unrecognised failure AmbiguousOrderError, routing to query-by-tag rather than a retry; only a 429 is retryable. Verified by mutation testing - breaking the fail-closed rule fails the test. The default disposition for an unknown code is now the safe one rather than an unspecified one.
A32: E03-S01 | B32: E03 | C32: HISTORICAL DATA | D32: NSE bhavcopy fetcher and archiver | E32: New | F32: P0 | G32: 1 | H32: Correctness-critical | I32: FEAT | J32: 1.5 | K32: E01-S02 | R32: 6 | S32: As a system, I need daily EOD data stored locally, so that pre-market analysis does not depend on a rate-limited API every morning. | T32: 1. Download bhavcopy for a given date 2. Parse and normalise to the `Bar` model 3. Idempotent upsert (re-running a date is safe) 4. Backfill utility for a date range 5. Handle holidays and missing files gracefully 6. Schedule at 05:30 | U32: • Backfilling 2 years completes and is re-runnable without duplicates | X32: NSE replaced the legacy bhavcopy with the UDiFF format and moved the URL. A fetcher written against the old path will 404, or worse fetch a stale mirror. Pin the exact source and assert on the header row, not just on HTTP 200. Also: bhavcopy is UNADJUSTED, so this must land before E03-S02 computes factors, never after.
A33: E03-S02 | B33: E03 | C33: HISTORICAL DATA | D33: Corporate action adjustment | E33: Development Completed | F33: P0 | G33: 1 | H33: Safety-critical | I33: FEAT | J33: 2 | K33: E03-S01 | L33: Feed only — B1/B4 (broker data source). Engine is complete. | Q33: 0.7 | R33: 5 | S33: As an analyst, I want historical prices adjusted for splits and bonuses, so that moving averages do not show phantom breakouts. | T33: 1. Fetch corporate action data — NOT DONE, needs a data source (see Blocked By) 2. [DONE] Store actions in `corporate_action` — the source of truth for adjustment 3. [DONE] Derive `price_adj_factor` / `volume_adj_factor` per bar; raw OHLC never mutated 4. [DONE] Re-adjustment when a new action is announced — full recompute, idempotent 5. [DONE] Verify against a known historical split | U33: • A known 1:5 split produces a continuous price series across the event • 🔴 Unadjusted data can never reach the indicator engine | V33: DESIGN BLOCKER RESOLVED 11 Aug 2026. See SPRINT02_TECHNICAL_SPEC.md §4 and CA-B1 on the Blockers sheet. THE BLOCKER: the schema specified `ohlcv.is_adjusted BOOLEAN`, which cannot support re-adjustment. When a second action arrives you need the factor ALREADY APPLIED in order to apply the next one, and a boolean does not carry it. Adjusting prices in place compounds silently — no exception, no failing test, just a permanently wrong price history. This is safety-critical because a wrong adjustment does not fail loudly; every backtest over the affected symbol simply becomes fiction. THE RESOLUTION: raw prices are never modified. A new `corporate_action` table is the source of truth, and each bar carries two derived factors — adjusted price = raw * price_adj_factor. Recompute always rebuilds from the FULL action history, which makes it idempotent, and makes a mis-entered action fixable by correcting its row and recomputing. TWO factors, not one: a dividend reduces price but leaves volume untouched, so a single reciprocal factor would corrupt volume on every dividend — and volume feeds both the liquidity filter and the volume-ratio indicator. BR-16 IS ENFORCED STRUCTURALLY, not by convention: BarRepository has no method that returns raw prices. The only accessor is `raw_bars_for_audit`, named to be hard to reach for, and a test asserts no raw-read sibling exists. The trading path cannot ask for unadjusted data by accident. | W33: 18 tests, all passing. Three findings came out of building it, each now covered by its own test: 1. ORDER INDEPENDENCE WAS ONLY APPROXIMATE. A Hypothesis property test caught that multiplying Decimal QUOTIENTS is not exactly associative — combining the same three splits in two different orders gave answers differing in the last digits. Fixed by keeping factors as exact ratios (numerator/denominator held separately) and dividing once at the end. Actions arrive from a feed in arbitrary order, so this had to be exact rather than nearly exact. 2. RESTORE FROM ARCHIVE MISSED ADJUSTMENTS. Archived bars are not in `ohlcv`, so any action recorded while they were away updated the live bars and skipped them. Restoring them would have spliced an unadjusted segment onto an adjusted series. `restore_bars` now recomputes factors for every restored symbol. 3. CONCURRENT RECOMPUTE COULD LOSE AN ACTION. Two recomputes for one symbol could interleave and the older action set could win. Row locks do not catch this because both writers are self-consistent. Now takes a per-symbol transaction-scoped advisory lock before reading, same pattern as the audit chain. ALSO: dividends are recorded but NOT applied to prices (APPLY_DIVIDEND_ADJUSTMENT = False). These are intraday strategies that never hold across an ex-date, and dividend adjustment rewrites every historical price. Flip it only alongside a decision about what backtests are measuring.
A34: E03-S03 | B34: E03 | C34: HISTORICAL DATA | D34: Intraday history backfill | E34: New | F34: P0 | G34: 1 | H34: Correctness-critical | I34: FEAT | J34: 1.5 | K34: E02-S03 | R34: 4 | S34: As a backtester, I need minute-level history, so that strategies can be validated on realistic intraday data. | T34: 1. Paged historical fetch respecting rate limits 2. Backfill orchestration across the universe 3. Resume from interruption 4. Progress reporting (this takes hours) | X34: PARTLY RESOLVED Aug 2026. Blocker B4 is gone: historical data is no longer a separate paid add-on. The free Personal tier carries NO data; Connect at Rs.500/month bundles real-time WebSocket AND historical candles. So this story needs a Rs.500 subscription, not Rs.2500. STILL LIVE: the rate limit and the per-request date-range cap remain, and a multi-hour backfill during market hours competes with live data on the same account-wide budget. Schedule it outside the session.
